ERROR 2025-07-05 21:33:10,345 log 4700 14808 Internal Server Error: /feed/
Traceback (most recent call last):
  File "C:\Users\Admin\AppData\Roaming\Python\Python313\site-packages\django\core\handlers\exception.py", line 55, in inner
    response = get_response(request)
  File "C:\Users\Admin\AppData\Roaming\Python\Python313\site-packages\django\core\handlers\base.py", line 197, in _get_response
    response = wrapped_callback(request, *callback_args, **callback_kwargs)
  File "C:\Users\Admin\AppData\Roaming\Python\Python313\site-packages\django\contrib\auth\decorators.py", line 23, in _wrapper_view
    return view_func(request, *args, **kwargs)
  File "D:\TEJASWI\my projects\projects\django project\anonymous_thought_board\thoughtify\views.py", line 71, in feed
    user_profile = request.user.userprofile
                   ^^^^^^^^^^^^^^^^^^^^^^^^
  File "C:\Users\Admin\AppData\Roaming\Python\Python313\site-packages\django\utils\functional.py", line 268, in inner
    return func(_wrapped, *args)
  File "C:\Users\Admin\AppData\Roaming\Python\Python313\site-packages\django\db\models\fields\related_descriptors.py", line 492, in __get__
    raise self.RelatedObjectDoesNotExist(
    ...<2 lines>...
    )
django.contrib.auth.models.User.userprofile.RelatedObjectDoesNotExist: User has no userprofile.
ERROR 2025-07-05 21:35:32,174 log 4700 14808 Internal Server Error: /feed/
Traceback (most recent call last):
  File "C:\Users\Admin\AppData\Roaming\Python\Python313\site-packages\django\core\handlers\exception.py", line 55, in inner
    response = get_response(request)
  File "C:\Users\Admin\AppData\Roaming\Python\Python313\site-packages\django\core\handlers\base.py", line 197, in _get_response
    response = wrapped_callback(request, *callback_args, **callback_kwargs)
  File "C:\Users\Admin\AppData\Roaming\Python\Python313\site-packages\django\contrib\auth\decorators.py", line 23, in _wrapper_view
    return view_func(request, *args, **kwargs)
  File "D:\TEJASWI\my projects\projects\django project\anonymous_thought_board\thoughtify\views.py", line 71, in feed
    user_profile = request.user.userprofile
                   ^^^^^^^^^^^^^^^^^^^^^^^^
  File "C:\Users\Admin\AppData\Roaming\Python\Python313\site-packages\django\utils\functional.py", line 268, in inner
    return func(_wrapped, *args)
  File "C:\Users\Admin\AppData\Roaming\Python\Python313\site-packages\django\db\models\fields\related_descriptors.py", line 492, in __get__
    raise self.RelatedObjectDoesNotExist(
    ...<2 lines>...
    )
django.contrib.auth.models.User.userprofile.RelatedObjectDoesNotExist: User has no userprofile.
ERROR 2025-07-05 21:45:07,267 log 5024 11308 Internal Server Error: /thought/create/
Traceback (most recent call last):
  File "C:\Users\Admin\AppData\Roaming\Python\Python313\site-packages\django\core\handlers\exception.py", line 55, in inner
    response = get_response(request)
  File "C:\Users\Admin\AppData\Roaming\Python\Python313\site-packages\django\core\handlers\base.py", line 197, in _get_response
    response = wrapped_callback(request, *callback_args, **callback_kwargs)
  File "C:\Users\Admin\AppData\Roaming\Python\Python313\site-packages\django\contrib\auth\decorators.py", line 23, in _wrapper_view
    return view_func(request, *args, **kwargs)
  File "D:\TEJASWI\my projects\projects\django project\anonymous_thought_board\thoughtify\views.py", line 129, in create_thought
    return render(request, 'thoughtify/create_thought.html', {'form': form})
  File "C:\Users\Admin\AppData\Roaming\Python\Python313\site-packages\django\shortcuts.py", line 24, in render
    content = loader.render_to_string(template_name, context, request, using=using)
  File "C:\Users\Admin\AppData\Roaming\Python\Python313\site-packages\django\template\loader.py", line 61, in render_to_string
    template = get_template(template_name, using=using)
  File "C:\Users\Admin\AppData\Roaming\Python\Python313\site-packages\django\template\loader.py", line 19, in get_template
    raise TemplateDoesNotExist(template_name, chain=chain)
django.template.exceptions.TemplateDoesNotExist: thoughtify/create_thought.html
ERROR 2025-07-05 22:02:36,415 log 6412 12156 Internal Server Error: /admin/thoughtify/thought/
Traceback (most recent call last):
  File "C:\Users\Admin\AppData\Roaming\Python\Python313\site-packages\django\db\models\options.py", line 681, in get_field
    return self.fields_map[field_name]
           ~~~~~~~~~~~~~~~^^^^^^^^^^^^
KeyError: 'author_code'

During handling of the above exception, another exception occurred:

Traceback (most recent call last):
  File "C:\Users\Admin\AppData\Roaming\Python\Python313\site-packages\django\contrib\admin\utils.py", line 272, in lookup_field
    f = _get_non_gfk_field(opts, name)
  File "C:\Users\Admin\AppData\Roaming\Python\Python313\site-packages\django\contrib\admin\utils.py", line 303, in _get_non_gfk_field
    field = opts.get_field(name)
  File "C:\Users\Admin\AppData\Roaming\Python\Python313\site-packages\django\db\models\options.py", line 683, in get_field
    raise FieldDoesNotExist(
        "%s has no field named '%s'" % (self.object_name, field_name)
    )
django.core.exceptions.FieldDoesNotExist: Thought has no field named 'author_code'

During handling of the above exception, another exception occurred:

Traceback (most recent call last):
  File "C:\Users\Admin\AppData\Roaming\Python\Python313\site-packages\django\core\handlers\exception.py", line 55, in inner
    response = get_response(request)
  File "C:\Users\Admin\AppData\Roaming\Python\Python313\site-packages\django\core\handlers\base.py", line 220, in _get_response
    response = response.render()
  File "C:\Users\Admin\AppData\Roaming\Python\Python313\site-packages\django\template\response.py", line 114, in render
    self.content = self.rendered_content
                   ^^^^^^^^^^^^^^^^^^^^^
  File "C:\Users\Admin\AppData\Roaming\Python\Python313\site-packages\django\template\response.py", line 92, in rendered_content
    return template.render(context, self._request)
           ~~~~~~~~~~~~~~~^^^^^^^^^^^^^^^^^^^^^^^^
  File "C:\Users\Admin\AppData\Roaming\Python\Python313\site-packages\django\template\backends\django.py", line 61, in render
    return self.template.render(context)
           ~~~~~~~~~~~~~~~~~~~~^^^^^^^^^
  File "C:\Users\Admin\AppData\Roaming\Python\Python313\site-packages\django\template\base.py", line 175, in render
    return self._render(context)
           ~~~~~~~~~~~~^^^^^^^^^
  File "C:\Users\Admin\AppData\Roaming\Python\Python313\site-packages\django\template\base.py", line 167, in _render
    return self.nodelist.render(context)
           ~~~~~~~~~~~~~~~~~~~~^^^^^^^^^
  File "C:\Users\Admin\AppData\Roaming\Python\Python313\site-packages\django\template\base.py", line 1005, in render
    return SafeString("".join([node.render_annotated(context) for node in self]))
                               ~~~~~~~~~~~~~~~~~~~~~^^^^^^^^^
  File "C:\Users\Admin\AppData\Roaming\Python\Python313\site-packages\django\template\base.py", line 966, in render_annotated
    return self.render(context)
           ~~~~~~~~~~~^^^^^^^^^
  File "C:\Users\Admin\AppData\Roaming\Python\Python313\site-packages\django\template\loader_tags.py", line 157, in render
    return compiled_parent._render(context)
           ~~~~~~~~~~~~~~~~~~~~~~~^^^^^^^^^
  File "C:\Users\Admin\AppData\Roaming\Python\Python313\site-packages\django\template\base.py", line 167, in _render
    return self.nodelist.render(context)
           ~~~~~~~~~~~~~~~~~~~~^^^^^^^^^
  File "C:\Users\Admin\AppData\Roaming\Python\Python313\site-packages\django\template\base.py", line 1005, in render
    return SafeString("".join([node.render_annotated(context) for node in self]))
                               ~~~~~~~~~~~~~~~~~~~~~^^^^^^^^^
  File "C:\Users\Admin\AppData\Roaming\Python\Python313\site-packages\django\template\base.py", line 966, in render_annotated
    return self.render(context)
           ~~~~~~~~~~~^^^^^^^^^
  File "C:\Users\Admin\AppData\Roaming\Python\Python313\site-packages\django\template\loader_tags.py", line 157, in render
    return compiled_parent._render(context)
           ~~~~~~~~~~~~~~~~~~~~~~~^^^^^^^^^
  File "C:\Users\Admin\AppData\Roaming\Python\Python313\site-packages\django\template\base.py", line 167, in _render
    return self.nodelist.render(context)
           ~~~~~~~~~~~~~~~~~~~~^^^^^^^^^
  File "C:\Users\Admin\AppData\Roaming\Python\Python313\site-packages\django\template\base.py", line 1005, in render
    return SafeString("".join([node.render_annotated(context) for node in self]))
                               ~~~~~~~~~~~~~~~~~~~~~^^^^^^^^^
  File "C:\Users\Admin\AppData\Roaming\Python\Python313\site-packages\django\template\base.py", line 966, in render_annotated
    return self.render(context)
           ~~~~~~~~~~~^^^^^^^^^
  File "C:\Users\Admin\AppData\Roaming\Python\Python313\site-packages\django\template\loader_tags.py", line 63, in render
    result = block.nodelist.render(context)
  File "C:\Users\Admin\AppData\Roaming\Python\Python313\site-packages\django\template\base.py", line 1005, in render
    return SafeString("".join([node.render_annotated(context) for node in self]))
                               ~~~~~~~~~~~~~~~~~~~~~^^^^^^^^^
  File "C:\Users\Admin\AppData\Roaming\Python\Python313\site-packages\django\template\base.py", line 966, in render_annotated
    return self.render(context)
           ~~~~~~~~~~~^^^^^^^^^
  File "C:\Users\Admin\AppData\Roaming\Python\Python313\site-packages\django\template\loader_tags.py", line 63, in render
    result = block.nodelist.render(context)
  File "C:\Users\Admin\AppData\Roaming\Python\Python313\site-packages\django\template\base.py", line 1005, in render
    return SafeString("".join([node.render_annotated(context) for node in self]))
                               ~~~~~~~~~~~~~~~~~~~~~^^^^^^^^^
  File "C:\Users\Admin\AppData\Roaming\Python\Python313\site-packages\django\template\base.py", line 966, in render_annotated
    return self.render(context)
           ~~~~~~~~~~~^^^^^^^^^
  File "C:\Users\Admin\AppData\Roaming\Python\Python313\site-packages\django\contrib\admin\templatetags\base.py", line 45, in render
    return super().render(context)
           ~~~~~~~~~~~~~~^^^^^^^^^
  File "C:\Users\Admin\AppData\Roaming\Python\Python313\site-packages\django\template\library.py", line 258, in render
    _dict = self.func(*resolved_args, **resolved_kwargs)
  File "C:\Users\Admin\AppData\Roaming\Python\Python313\site-packages\django\contrib\admin\templatetags\admin_list.py", line 336, in result_list
    "results": list(results(cl)),
               ~~~~^^^^^^^^^^^^^
  File "C:\Users\Admin\AppData\Roaming\Python\Python313\site-packages\django\contrib\admin\templatetags\admin_list.py", line 312, in results
    yield ResultList(None, items_for_result(cl, res, None))
          ~~~~~~~~~~^^^^^^^^^^^^^^^^^^^^^^^^^^^^^^^^^^^^^^^
  File "C:\Users\Admin\AppData\Roaming\Python\Python313\site-packages\django\contrib\admin\templatetags\admin_list.py", line 303, in __init__
    super().__init__(*items)
    ~~~~~~~~~~~~~~~~^^^^^^^^
  File "C:\Users\Admin\AppData\Roaming\Python\Python313\site-packages\django\contrib\admin\templatetags\admin_list.py", line 213, in items_for_result
    f, attr, value = lookup_field(field_name, result, cl.model_admin)
                     ~~~~~~~~~~~~^^^^^^^^^^^^^^^^^^^^^^^^^^^^^^^^^^^^
  File "C:\Users\Admin\AppData\Roaming\Python\Python313\site-packages\django\contrib\admin\utils.py", line 281, in lookup_field
    value = attr(obj)
  File "D:\TEJASWI\my projects\projects\django project\anonymous_thought_board\thoughtify\admin.py", line 34, in author_code
    return obj.author.userprofile.anonymous_code
           ^^^^^^^^^^^^^^^^^^^^^^
AttributeError: 'NoneType' object has no attribute 'userprofile'
ERROR 2025-07-05 22:03:37,249 log 6412 7880 Internal Server Error: /admin/thoughtify/thought/
Traceback (most recent call last):
  File "C:\Users\Admin\AppData\Roaming\Python\Python313\site-packages\django\db\models\options.py", line 681, in get_field
    return self.fields_map[field_name]
           ~~~~~~~~~~~~~~~^^^^^^^^^^^^
KeyError: 'author_code'

During handling of the above exception, another exception occurred:

Traceback (most recent call last):
  File "C:\Users\Admin\AppData\Roaming\Python\Python313\site-packages\django\contrib\admin\utils.py", line 272, in lookup_field
    f = _get_non_gfk_field(opts, name)
  File "C:\Users\Admin\AppData\Roaming\Python\Python313\site-packages\django\contrib\admin\utils.py", line 303, in _get_non_gfk_field
    field = opts.get_field(name)
  File "C:\Users\Admin\AppData\Roaming\Python\Python313\site-packages\django\db\models\options.py", line 683, in get_field
    raise FieldDoesNotExist(
        "%s has no field named '%s'" % (self.object_name, field_name)
    )
django.core.exceptions.FieldDoesNotExist: Thought has no field named 'author_code'

During handling of the above exception, another exception occurred:

Traceback (most recent call last):
  File "C:\Users\Admin\AppData\Roaming\Python\Python313\site-packages\django\core\handlers\exception.py", line 55, in inner
    response = get_response(request)
  File "C:\Users\Admin\AppData\Roaming\Python\Python313\site-packages\django\core\handlers\base.py", line 220, in _get_response
    response = response.render()
  File "C:\Users\Admin\AppData\Roaming\Python\Python313\site-packages\django\template\response.py", line 114, in render
    self.content = self.rendered_content
                   ^^^^^^^^^^^^^^^^^^^^^
  File "C:\Users\Admin\AppData\Roaming\Python\Python313\site-packages\django\template\response.py", line 92, in rendered_content
    return template.render(context, self._request)
           ~~~~~~~~~~~~~~~^^^^^^^^^^^^^^^^^^^^^^^^
  File "C:\Users\Admin\AppData\Roaming\Python\Python313\site-packages\django\template\backends\django.py", line 61, in render
    return self.template.render(context)
           ~~~~~~~~~~~~~~~~~~~~^^^^^^^^^
  File "C:\Users\Admin\AppData\Roaming\Python\Python313\site-packages\django\template\base.py", line 175, in render
    return self._render(context)
           ~~~~~~~~~~~~^^^^^^^^^
  File "C:\Users\Admin\AppData\Roaming\Python\Python313\site-packages\django\template\base.py", line 167, in _render
    return self.nodelist.render(context)
           ~~~~~~~~~~~~~~~~~~~~^^^^^^^^^
  File "C:\Users\Admin\AppData\Roaming\Python\Python313\site-packages\django\template\base.py", line 1005, in render
    return SafeString("".join([node.render_annotated(context) for node in self]))
                               ~~~~~~~~~~~~~~~~~~~~~^^^^^^^^^
  File "C:\Users\Admin\AppData\Roaming\Python\Python313\site-packages\django\template\base.py", line 966, in render_annotated
    return self.render(context)
           ~~~~~~~~~~~^^^^^^^^^
  File "C:\Users\Admin\AppData\Roaming\Python\Python313\site-packages\django\template\loader_tags.py", line 157, in render
    return compiled_parent._render(context)
           ~~~~~~~~~~~~~~~~~~~~~~~^^^^^^^^^
  File "C:\Users\Admin\AppData\Roaming\Python\Python313\site-packages\django\template\base.py", line 167, in _render
    return self.nodelist.render(context)
           ~~~~~~~~~~~~~~~~~~~~^^^^^^^^^
  File "C:\Users\Admin\AppData\Roaming\Python\Python313\site-packages\django\template\base.py", line 1005, in render
    return SafeString("".join([node.render_annotated(context) for node in self]))
                               ~~~~~~~~~~~~~~~~~~~~~^^^^^^^^^
  File "C:\Users\Admin\AppData\Roaming\Python\Python313\site-packages\django\template\base.py", line 966, in render_annotated
    return self.render(context)
           ~~~~~~~~~~~^^^^^^^^^
  File "C:\Users\Admin\AppData\Roaming\Python\Python313\site-packages\django\template\loader_tags.py", line 157, in render
    return compiled_parent._render(context)
           ~~~~~~~~~~~~~~~~~~~~~~~^^^^^^^^^
  File "C:\Users\Admin\AppData\Roaming\Python\Python313\site-packages\django\template\base.py", line 167, in _render
    return self.nodelist.render(context)
           ~~~~~~~~~~~~~~~~~~~~^^^^^^^^^
  File "C:\Users\Admin\AppData\Roaming\Python\Python313\site-packages\django\template\base.py", line 1005, in render
    return SafeString("".join([node.render_annotated(context) for node in self]))
                               ~~~~~~~~~~~~~~~~~~~~~^^^^^^^^^
  File "C:\Users\Admin\AppData\Roaming\Python\Python313\site-packages\django\template\base.py", line 966, in render_annotated
    return self.render(context)
           ~~~~~~~~~~~^^^^^^^^^
  File "C:\Users\Admin\AppData\Roaming\Python\Python313\site-packages\django\template\loader_tags.py", line 63, in render
    result = block.nodelist.render(context)
  File "C:\Users\Admin\AppData\Roaming\Python\Python313\site-packages\django\template\base.py", line 1005, in render
    return SafeString("".join([node.render_annotated(context) for node in self]))
                               ~~~~~~~~~~~~~~~~~~~~~^^^^^^^^^
  File "C:\Users\Admin\AppData\Roaming\Python\Python313\site-packages\django\template\base.py", line 966, in render_annotated
    return self.render(context)
           ~~~~~~~~~~~^^^^^^^^^
  File "C:\Users\Admin\AppData\Roaming\Python\Python313\site-packages\django\template\loader_tags.py", line 63, in render
    result = block.nodelist.render(context)
  File "C:\Users\Admin\AppData\Roaming\Python\Python313\site-packages\django\template\base.py", line 1005, in render
    return SafeString("".join([node.render_annotated(context) for node in self]))
                               ~~~~~~~~~~~~~~~~~~~~~^^^^^^^^^
  File "C:\Users\Admin\AppData\Roaming\Python\Python313\site-packages\django\template\base.py", line 966, in render_annotated
    return self.render(context)
           ~~~~~~~~~~~^^^^^^^^^
  File "C:\Users\Admin\AppData\Roaming\Python\Python313\site-packages\django\contrib\admin\templatetags\base.py", line 45, in render
    return super().render(context)
           ~~~~~~~~~~~~~~^^^^^^^^^
  File "C:\Users\Admin\AppData\Roaming\Python\Python313\site-packages\django\template\library.py", line 258, in render
    _dict = self.func(*resolved_args, **resolved_kwargs)
  File "C:\Users\Admin\AppData\Roaming\Python\Python313\site-packages\django\contrib\admin\templatetags\admin_list.py", line 336, in result_list
    "results": list(results(cl)),
               ~~~~^^^^^^^^^^^^^
  File "C:\Users\Admin\AppData\Roaming\Python\Python313\site-packages\django\contrib\admin\templatetags\admin_list.py", line 312, in results
    yield ResultList(None, items_for_result(cl, res, None))
          ~~~~~~~~~~^^^^^^^^^^^^^^^^^^^^^^^^^^^^^^^^^^^^^^^
  File "C:\Users\Admin\AppData\Roaming\Python\Python313\site-packages\django\contrib\admin\templatetags\admin_list.py", line 303, in __init__
    super().__init__(*items)
    ~~~~~~~~~~~~~~~~^^^^^^^^
  File "C:\Users\Admin\AppData\Roaming\Python\Python313\site-packages\django\contrib\admin\templatetags\admin_list.py", line 213, in items_for_result
    f, attr, value = lookup_field(field_name, result, cl.model_admin)
                     ~~~~~~~~~~~~^^^^^^^^^^^^^^^^^^^^^^^^^^^^^^^^^^^^
  File "C:\Users\Admin\AppData\Roaming\Python\Python313\site-packages\django\contrib\admin\utils.py", line 281, in lookup_field
    value = attr(obj)
  File "D:\TEJASWI\my projects\projects\django project\anonymous_thought_board\thoughtify\admin.py", line 34, in author_code
    return obj.author.userprofile.anonymous_code
           ^^^^^^^^^^^^^^^^^^^^^^
AttributeError: 'NoneType' object has no attribute 'userprofile'
ERROR 2025-07-05 22:09:58,848 log 3216 11560 Internal Server Error: /feed/
Traceback (most recent call last):
  File "C:\Users\Admin\AppData\Roaming\Python\Python313\site-packages\django\core\handlers\exception.py", line 55, in inner
    response = get_response(request)
  File "C:\Users\Admin\AppData\Roaming\Python\Python313\site-packages\django\core\handlers\base.py", line 197, in _get_response
    response = wrapped_callback(request, *callback_args, **callback_kwargs)
  File "C:\Users\Admin\AppData\Roaming\Python\Python313\site-packages\django\contrib\auth\decorators.py", line 23, in _wrapper_view
    return view_func(request, *args, **kwargs)
  File "D:\TEJASWI\my projects\projects\django project\anonymous_thought_board\thoughtify\views.py", line 71, in feed
    user_profile = request.user.userprofile
                   ^^^^^^^^^^^^^^^^^^^^^^^^
  File "C:\Users\Admin\AppData\Roaming\Python\Python313\site-packages\django\utils\functional.py", line 268, in inner
    return func(_wrapped, *args)
  File "C:\Users\Admin\AppData\Roaming\Python\Python313\site-packages\django\db\models\fields\related_descriptors.py", line 492, in __get__
    raise self.RelatedObjectDoesNotExist(
    ...<2 lines>...
    )
django.contrib.auth.models.User.userprofile.RelatedObjectDoesNotExist: User has no userprofile.
ERROR 2025-07-05 22:14:11,088 log 3216 11560 Internal Server Error: /feed/
Traceback (most recent call last):
  File "C:\Users\Admin\AppData\Roaming\Python\Python313\site-packages\django\core\handlers\exception.py", line 55, in inner
    response = get_response(request)
  File "C:\Users\Admin\AppData\Roaming\Python\Python313\site-packages\django\core\handlers\base.py", line 197, in _get_response
    response = wrapped_callback(request, *callback_args, **callback_kwargs)
  File "C:\Users\Admin\AppData\Roaming\Python\Python313\site-packages\django\contrib\auth\decorators.py", line 23, in _wrapper_view
    return view_func(request, *args, **kwargs)
  File "D:\TEJASWI\my projects\projects\django project\anonymous_thought_board\thoughtify\views.py", line 71, in feed
    user_profile = request.user.userprofile
                   ^^^^^^^^^^^^^^^^^^^^^^^^
  File "C:\Users\Admin\AppData\Roaming\Python\Python313\site-packages\django\utils\functional.py", line 268, in inner
    return func(_wrapped, *args)
  File "C:\Users\Admin\AppData\Roaming\Python\Python313\site-packages\django\db\models\fields\related_descriptors.py", line 492, in __get__
    raise self.RelatedObjectDoesNotExist(
    ...<2 lines>...
    )
django.contrib.auth.models.User.userprofile.RelatedObjectDoesNotExist: User has no userprofile.
ERROR 2025-07-05 22:14:13,122 log 3216 11560 Internal Server Error: /feed/
Traceback (most recent call last):
  File "C:\Users\Admin\AppData\Roaming\Python\Python313\site-packages\django\core\handlers\exception.py", line 55, in inner
    response = get_response(request)
  File "C:\Users\Admin\AppData\Roaming\Python\Python313\site-packages\django\core\handlers\base.py", line 197, in _get_response
    response = wrapped_callback(request, *callback_args, **callback_kwargs)
  File "C:\Users\Admin\AppData\Roaming\Python\Python313\site-packages\django\contrib\auth\decorators.py", line 23, in _wrapper_view
    return view_func(request, *args, **kwargs)
  File "D:\TEJASWI\my projects\projects\django project\anonymous_thought_board\thoughtify\views.py", line 71, in feed
    user_profile = request.user.userprofile
                   ^^^^^^^^^^^^^^^^^^^^^^^^
  File "C:\Users\Admin\AppData\Roaming\Python\Python313\site-packages\django\utils\functional.py", line 268, in inner
    return func(_wrapped, *args)
  File "C:\Users\Admin\AppData\Roaming\Python\Python313\site-packages\django\db\models\fields\related_descriptors.py", line 492, in __get__
    raise self.RelatedObjectDoesNotExist(
    ...<2 lines>...
    )
django.contrib.auth.models.User.userprofile.RelatedObjectDoesNotExist: User has no userprofile.
ERROR 2025-07-05 22:14:22,928 log 3216 11560 Internal Server Error: /feed/
Traceback (most recent call last):
  File "C:\Users\Admin\AppData\Roaming\Python\Python313\site-packages\django\core\handlers\exception.py", line 55, in inner
    response = get_response(request)
  File "C:\Users\Admin\AppData\Roaming\Python\Python313\site-packages\django\core\handlers\base.py", line 197, in _get_response
    response = wrapped_callback(request, *callback_args, **callback_kwargs)
  File "C:\Users\Admin\AppData\Roaming\Python\Python313\site-packages\django\contrib\auth\decorators.py", line 23, in _wrapper_view
    return view_func(request, *args, **kwargs)
  File "D:\TEJASWI\my projects\projects\django project\anonymous_thought_board\thoughtify\views.py", line 71, in feed
    user_profile = request.user.userprofile
                   ^^^^^^^^^^^^^^^^^^^^^^^^
  File "C:\Users\Admin\AppData\Roaming\Python\Python313\site-packages\django\utils\functional.py", line 268, in inner
    return func(_wrapped, *args)
  File "C:\Users\Admin\AppData\Roaming\Python\Python313\site-packages\django\db\models\fields\related_descriptors.py", line 492, in __get__
    raise self.RelatedObjectDoesNotExist(
    ...<2 lines>...
    )
django.contrib.auth.models.User.userprofile.RelatedObjectDoesNotExist: User has no userprofile.
ERROR 2025-07-05 22:17:52,544 log 3216 9396 Internal Server Error: /thought/85/update/
Traceback (most recent call last):
  File "C:\Users\Admin\AppData\Roaming\Python\Python313\site-packages\django\core\handlers\exception.py", line 55, in inner
    response = get_response(request)
  File "C:\Users\Admin\AppData\Roaming\Python\Python313\site-packages\django\core\handlers\base.py", line 197, in _get_response
    response = wrapped_callback(request, *callback_args, **callback_kwargs)
  File "C:\Users\Admin\AppData\Roaming\Python\Python313\site-packages\django\contrib\auth\decorators.py", line 23, in _wrapper_view
    return view_func(request, *args, **kwargs)
  File "D:\TEJASWI\my projects\projects\django project\anonymous_thought_board\thoughtify\views.py", line 150, in update_thought
    return render(request, 'thoughtify/update_thought.html', {
        'form': form,
        'thought': thought
    })
  File "C:\Users\Admin\AppData\Roaming\Python\Python313\site-packages\django\shortcuts.py", line 24, in render
    content = loader.render_to_string(template_name, context, request, using=using)
  File "C:\Users\Admin\AppData\Roaming\Python\Python313\site-packages\django\template\loader.py", line 61, in render_to_string
    template = get_template(template_name, using=using)
  File "C:\Users\Admin\AppData\Roaming\Python\Python313\site-packages\django\template\loader.py", line 19, in get_template
    raise TemplateDoesNotExist(template_name, chain=chain)
django.template.exceptions.TemplateDoesNotExist: thoughtify/update_thought.html
